{"timestamp":"2025-05-21T02:41:31.183Z","error":{"name":"Error","message":"Processing completed but no result file was generated","stack":"Error: Processing completed but no result file was generated\n    at /Users/ramtinabolfazli/Documents/Work/Seniors and Juniors/Program/server/routes/process.js:124:27\n    at process.processTicksAndRejections (node:internal/process/task_queues:105:5)"},"context":{"requestId":1747795176275,"locationNumber":"12345","timestamp":"2025-05-21T02:41:31.181Z"}}
{"timestamp":"2025-05-22T00:15:12.202Z","error":{"name":"Error","message":"Processing completed but no result file was generated","stack":"Error: Processing completed but no result file was generated\n    at /Users/ramtinabolfazli/Documents/Work/Seniors and Juniors/Program/server/routes/process.js:124:27"},"context":{"requestId":1747872891112,"locationNumber":"12345","timestamp":"2025-05-22T00:15:12.202Z"}}
{"timestamp":"2025-05-22T00:20:37.505Z","error":{"name":"Error","message":"Processing completed but no result file was generated","stack":"Error: Processing completed but no result file was generated\n    at /Users/ramtinabolfazli/Documents/Work/Seniors and Juniors/Program/server/routes/process.js:124:27\n    at process.processTicksAndRejections (node:internal/process/task_queues:105:5)"},"context":{"requestId":1747873218737,"locationNumber":"12345","timestamp":"2025-05-22T00:20:37.505Z"}}
{"timestamp":"2025-05-22T00:28:11.493Z","error":{"name":"Error","message":"Processing completed but no result file was generated","stack":"Error: Processing completed but no result file was generated\n    at /Users/ramtinabolfazli/Documents/Work/Seniors and Juniors/Program/server/routes/process.js:124:27\n    at process.processTicksAndRejections (node:internal/process/task_queues:105:5)"},"context":{"requestId":1747873682477,"locationNumber":"12345","timestamp":"2025-05-22T00:28:11.493Z"}}
{"timestamp":"2025-05-22T00:32:26.332Z","error":{"name":"Error","message":"Processing completed but no result file was generated","stack":"Error: Processing completed but no result file was generated\n    at /Users/ramtinabolfazli/Documents/Work/Seniors and Juniors/Program/server/routes/process.js:124:27\n    at process.processTicksAndRejections (node:internal/process/task_queues:105:5)"},"context":{"requestId":1747873933385,"locationNumber":"1234789","timestamp":"2025-05-22T00:32:26.332Z"}}
{"timestamp":"2025-05-22T00:35:54.740Z","error":{"name":"Error","message":"Processing completed but no result file was generated","stack":"Error: Processing completed but no result file was generated\n    at /Users/ramtinabolfazli/Documents/Work/Seniors and Juniors/Program/server/routes/process.js:124:27"},"context":{"requestId":1747874144499,"locationNumber":"1234789","timestamp":"2025-05-22T00:35:54.740Z"}}
{"timestamp":"2025-05-22T00:40:54.426Z","error":{"name":"Error","message":"Processing completed but no result file was generated","stack":"Error: Processing completed but no result file was generated\n    at /Users/ramtinabolfazli/Documents/Work/Seniors and Juniors/Program/server/routes/process.js:124:27\n    at process.processTicksAndRejections (node:internal/process/task_queues:105:5)"},"context":{"requestId":1747874444798,"locationNumber":"1234789","timestamp":"2025-05-22T00:40:54.426Z"}}
{"timestamp":"2025-05-22T00:49:14.587Z","error":{"name":"Error","message":"Processing completed but no result file was generated","stack":"Error: Processing completed but no result file was generated\n    at /Users/ramtinabolfazli/Documents/Work/Seniors and Juniors/Program/server/routes/process.js:124:27\n    at process.processTicksAndRejections (node:internal/process/task_queues:105:5)"},"context":{"requestId":1747874944260,"locationNumber":"1234789","timestamp":"2025-05-22T00:49:14.587Z"}}
{"timestamp":"2025-05-22T00:54:06.778Z","error":{"name":"Error","message":"Processing completed but no result file was generated","stack":"Error: Processing completed but no result file was generated\n    at /Users/ramtinabolfazli/Documents/Work/Seniors and Juniors/Program/server/routes/process.js:124:27\n    at process.processTicksAndRejections (node:internal/process/task_queues:105:5)"},"context":{"requestId":1747875241737,"locationNumber":"1234789","timestamp":"2025-05-22T00:54:06.778Z"}}
{"timestamp":"2025-05-22T01:06:08.903Z","error":{"name":"Error","message":"Processing completed but no result file was generated","stack":"Error: Processing completed but no result file was generated\n    at /Users/ramtinabolfazli/Documents/Work/Seniors and Juniors/Program/server/routes/process.js:124:27"},"context":{"requestId":1747875962199,"locationNumber":"1234789","timestamp":"2025-05-22T01:06:08.903Z"}}
{"timestamp":"2025-05-22T01:08:45.167Z","error":{"name":"Error","message":"Processing completed but no result file was generated","stack":"Error: Processing completed but no result file was generated\n    at /Users/ramtinabolfazli/Documents/Work/Seniors and Juniors/Program/server/routes/process.js:124:27\n    at process.processTicksAndRejections (node:internal/process/task_queues:105:5)"},"context":{"requestId":1747876101428,"locationNumber":"1234789","timestamp":"2025-05-22T01:08:45.166Z"}}
{"timestamp":"2025-05-22T01:12:33.728Z","error":{"name":"Error","message":"Processing completed but no result file was generated","stack":"Error: Processing completed but no result file was generated\n    at /Users/ramtinabolfazli/Documents/Work/Seniors and Juniors/Program/server/routes/process.js:124:27"},"context":{"requestId":1747876330759,"locationNumber":"1234789","timestamp":"2025-05-22T01:12:33.728Z"}}
{"timestamp":"2025-05-22T02:40:04.278Z","error":{"name":"Error","message":"Processing completed but no result file was generated","stack":"Error: Processing completed but no result file was generated\n    at /Users/ramtinabolfazli/Documents/Work/Seniors and Juniors/Program/server/routes/process.js:124:27"},"context":{"requestId":1747881587202,"locationNumber":"132232","timestamp":"2025-05-22T02:40:04.278Z"}}
{"timestamp":"2025-05-22T20:49:12.588Z","error":{"name":"Error","message":"Processing completed but no result file was generated","stack":"Error: Processing completed but no result file was generated\n    at /Users/ramtinabolfazli/Documents/Work/Seniors and Juniors/Program/server/routes/process.js:124:27\n    at process.processTicksAndRejections (node:internal/process/task_queues:105:5)"},"context":{"requestId":1747946837874,"locationNumber":"777","timestamp":"2025-05-22T20:49:12.583Z"}}
{"timestamp":"2025-05-22T20:53:14.756Z","error":{"name":"Error","message":"Processing completed but no result file was generated","stack":"Error: Processing completed but no result file was generated\n    at /Users/ramtinabolfazli/Documents/Work/Seniors and Juniors/Program/server/routes/process.js:124:27"},"context":{"requestId":1747947099400,"locationNumber":"777","timestamp":"2025-05-22T20:53:14.756Z"}}
{"timestamp":"2025-05-23T14:09:42.950Z","error":{"name":"Error","message":"Processing completed but no result file was generated","stack":"Error: Processing completed but no result file was generated\n    at /Users/ramtinabolfazli/Documents/Work/Seniors and Juniors/Program/server/routes/process.js:124:27\n    at process.processTicksAndRejections (node:internal/process/task_queues:105:5)"},"context":{"requestId":1748009375411,"locationNumber":"7778","timestamp":"2025-05-23T14:09:42.950Z"}}
{"timestamp":"2025-05-23T14:34:50.022Z","error":{"name":"Error","message":"Processing completed but no result file was generated","stack":"Error: Processing completed but no result file was generated\n    at /Users/ramtinabolfazli/Documents/Work/Seniors and Juniors/Program/server/routes/process.js:124:27"},"context":{"requestId":1748010864900,"locationNumber":"7778","timestamp":"2025-05-23T14:34:50.022Z"}}
{"timestamp":"2025-05-23T17:34:49.628Z","error":{"name":"Error","message":"JHA ID is required","stack":"Error: JHA ID is required\n    at /Users/ramtinabolfazli/Documents/Work/Seniors and Juniors/Program/server/routes/jhaprocess.js:32:27\n    at Layer.handle [as handle_request] (/Users/ramtinabolfazli/Documents/Work/Seniors and Juniors/Program/server/node_modules/express/lib/router/layer.js:95:5)\n    at next (/Users/ramtinabolfazli/Documents/Work/Seniors and Juniors/Program/server/node_modules/express/lib/router/route.js:149:13)\n    at Route.dispatch (/Users/ramtinabolfazli/Documents/Work/Seniors and Juniors/Program/server/node_modules/express/lib/router/route.js:119:3)\n    at Layer.handle [as handle_request] (/Users/ramtinabolfazli/Documents/Work/Seniors and Juniors/Program/server/node_modules/express/lib/router/layer.js:95:5)\n    at /Users/ramtinabolfazli/Documents/Work/Seniors and Juniors/Program/server/node_modules/express/lib/router/index.js:284:15\n    at Function.process_params (/Users/ramtinabolfazli/Documents/Work/Seniors and Juniors/Program/server/node_modules/express/lib/router/index.js:346:12)\n    at next (/Users/ramtinabolfazli/Documents/Work/Seniors and Juniors/Program/server/node_modules/express/lib/router/index.js:280:10)\n    at Function.handle (/Users/ramtinabolfazli/Documents/Work/Seniors and Juniors/Program/server/node_modules/express/lib/router/index.js:175:3)\n    at router (/Users/ramtinabolfazli/Documents/Work/Seniors and Juniors/Program/server/node_modules/express/lib/router/index.js:47:12)"},"context":{"requestId":1748021689627}}
{"timestamp":"2025-05-23T18:28:17.259Z","error":{"name":"Error","message":"No valid documents found for location 12345","stack":"Error: No valid documents found for location 12345\n    at /Users/ramtinabolfazli/Documents/Work/Seniors and Juniors/Program/server/routes/jhaprocess.js:61:27\n    at Layer.handle [as handle_request] (/Users/ramtinabolfazli/Documents/Work/Seniors and Juniors/Program/server/node_modules/express/lib/router/layer.js:95:5)\n    at next (/Users/ramtinabolfazli/Documents/Work/Seniors and Juniors/Program/server/node_modules/express/lib/router/route.js:149:13)\n    at Route.dispatch (/Users/ramtinabolfazli/Documents/Work/Seniors and Juniors/Program/server/node_modules/express/lib/router/route.js:119:3)\n    at Layer.handle [as handle_request] (/Users/ramtinabolfazli/Documents/Work/Seniors and Juniors/Program/server/node_modules/express/lib/router/layer.js:95:5)\n    at /Users/ramtinabolfazli/Documents/Work/Seniors and Juniors/Program/server/node_modules/express/lib/router/index.js:284:15\n    at param (/Users/ramtinabolfazli/Documents/Work/Seniors and Juniors/Program/server/node_modules/express/lib/router/index.js:365:14)\n    at param (/Users/ramtinabolfazli/Documents/Work/Seniors and Juniors/Program/server/node_modules/express/lib/router/index.js:376:14)\n    at Function.process_params (/Users/ramtinabolfazli/Documents/Work/Seniors and Juniors/Program/server/node_modules/express/lib/router/index.js:421:3)\n    at next (/Users/ramtinabolfazli/Documents/Work/Seniors and Juniors/Program/server/node_modules/express/lib/router/index.js:280:10)"},"context":{"requestId":1748024897255,"location":"12345"}}
{"timestamp":"2025-05-23T18:28:51.838Z","error":{"name":"Error","message":"No valid documents found for location 12345","stack":"Error: No valid documents found for location 12345\n    at /Users/ramtinabolfazli/Documents/Work/Seniors and Juniors/Program/server/routes/jhaprocess.js:61:27\n    at Layer.handle [as handle_request] (/Users/ramtinabolfazli/Documents/Work/Seniors and Juniors/Program/server/node_modules/express/lib/router/layer.js:95:5)\n    at next (/Users/ramtinabolfazli/Documents/Work/Seniors and Juniors/Program/server/node_modules/express/lib/router/route.js:149:13)\n    at Route.dispatch (/Users/ramtinabolfazli/Documents/Work/Seniors and Juniors/Program/server/node_modules/express/lib/router/route.js:119:3)\n    at Layer.handle [as handle_request] (/Users/ramtinabolfazli/Documents/Work/Seniors and Juniors/Program/server/node_modules/express/lib/router/layer.js:95:5)\n    at /Users/ramtinabolfazli/Documents/Work/Seniors and Juniors/Program/server/node_modules/express/lib/router/index.js:284:15\n    at param (/Users/ramtinabolfazli/Documents/Work/Seniors and Juniors/Program/server/node_modules/express/lib/router/index.js:365:14)\n    at param (/Users/ramtinabolfazli/Documents/Work/Seniors and Juniors/Program/server/node_modules/express/lib/router/index.js:376:14)\n    at Function.process_params (/Users/ramtinabolfazli/Documents/Work/Seniors and Juniors/Program/server/node_modules/express/lib/router/index.js:421:3)\n    at next (/Users/ramtinabolfazli/Documents/Work/Seniors and Juniors/Program/server/node_modules/express/lib/router/index.js:280:10)"},"context":{"requestId":1748024931837,"location":"12345"}}
{"timestamp":"2025-05-23T18:34:49.543Z","error":{"name":"Error","message":"Command failed: python \"/Users/ramtinabolfazli/Documents/Work/Seniors and Juniors/Program/server/python/process_jha.py\" --location \"12345\" --output \"/Users/ramtinabolfazli/Documents/Work/Seniors and Juniors/Program/output\" --uploads_root \"/Users/ramtinabolfazli/Documents/Work/Seniors and Juniors/Program/uploads\"\nTraceback (most recent call last):\n  File \"/Users/ramtinabolfazli/Documents/Work/Seniors and Juniors/Program/server/python/process_jha.py\", line 143, in <module>\n    main()\n  File \"/Users/ramtinabolfazli/Documents/Work/Seniors and Juniors/Program/server/python/process_jha.py\", line 134, in main\n    jha_data = process_pdf_files()\n               ^^^^^^^^^^^^^^^^^^^\n  File \"/Users/ramtinabolfazli/Documents/Work/Seniors and Juniors/Program/server/python/process_jha.py\", line 68, in process_pdf_files\n    [f for f in os.listdir(PDF_DIR) if f.endswith('.pdf')],\n                ^^^^^^^^^^^^^^^^^^^\nFileNotFoundError: [Errno 2] No such file or directory: 'pdf_files'\n","stack":"Error: Command failed: python \"/Users/ramtinabolfazli/Documents/Work/Seniors and Juniors/Program/server/python/process_jha.py\" --location \"12345\" --output \"/Users/ramtinabolfazli/Documents/Work/Seniors and Juniors/Program/output\" --uploads_root \"/Users/ramtinabolfazli/Documents/Work/Seniors and Juniors/Program/uploads\"\nTraceback (most recent call last):\n  File \"/Users/ramtinabolfazli/Documents/Work/Seniors and Juniors/Program/server/python/process_jha.py\", line 143, in <module>\n    main()\n  File \"/Users/ramtinabolfazli/Documents/Work/Seniors and Juniors/Program/server/python/process_jha.py\", line 134, in main\n    jha_data = process_pdf_files()\n               ^^^^^^^^^^^^^^^^^^^\n  File \"/Users/ramtinabolfazli/Documents/Work/Seniors and Juniors/Program/server/python/process_jha.py\", line 68, in process_pdf_files\n    [f for f in os.listdir(PDF_DIR) if f.endswith('.pdf')],\n                ^^^^^^^^^^^^^^^^^^^\nFileNotFoundError: [Errno 2] No such file or directory: 'pdf_files'\n\n    at genericNodeError (node:internal/errors:983:15)\n    at wrappedFn (node:internal/errors:537:14)\n    at ChildProcess.exithandler (node:child_process:414:12)\n    at ChildProcess.emit (node:events:507:28)\n    at maybeClose (node:internal/child_process:1101:16)\n    at ChildProcess._handle.onexit (node:internal/child_process:305:5)"},"context":{"requestId":1748025285388,"location":"12345"}}
{"timestamp":"2025-05-23T18:37:37.578Z","error":{"name":"Error","message":"Command failed: python \"/Users/ramtinabolfazli/Documents/Work/Seniors and Juniors/Program/server/python/process_jha.py\" --location \"12345\" --output \"/Users/ramtinabolfazli/Documents/Work/Seniors and Juniors/Program/output\" --uploads_root \"/Users/ramtinabolfazli/Documents/Work/Seniors and Juniors/Program/uploads\"\nTraceback (most recent call last):\n  File \"/Users/ramtinabolfazli/Documents/Work/Seniors and Juniors/Program/server/python/process_jha.py\", line 18, in <module>\n    UPLOADS_ROOT = args.uploads_root\n                   ^^^^\nNameError: name 'args' is not defined\n","stack":"Error: Command failed: python \"/Users/ramtinabolfazli/Documents/Work/Seniors and Juniors/Program/server/python/process_jha.py\" --location \"12345\" --output \"/Users/ramtinabolfazli/Documents/Work/Seniors and Juniors/Program/output\" --uploads_root \"/Users/ramtinabolfazli/Documents/Work/Seniors and Juniors/Program/uploads\"\nTraceback (most recent call last):\n  File \"/Users/ramtinabolfazli/Documents/Work/Seniors and Juniors/Program/server/python/process_jha.py\", line 18, in <module>\n    UPLOADS_ROOT = args.uploads_root\n                   ^^^^\nNameError: name 'args' is not defined\n\n    at genericNodeError (node:internal/errors:983:15)\n    at wrappedFn (node:internal/errors:537:14)\n    at ChildProcess.exithandler (node:child_process:414:12)\n    at ChildProcess.emit (node:events:507:28)\n    at maybeClose (node:internal/child_process:1101:16)\n    at ChildProcess._handle.onexit (node:internal/child_process:305:5)"},"context":{"requestId":1748025454826,"location":"12345"}}
{"timestamp":"2025-05-23T18:41:04.012Z","error":{"name":"Error","message":"Command failed: python \"/Users/ramtinabolfazli/Documents/Work/Seniors and Juniors/Program/server/python/process_jha.py\" --location \"12345\" --output \"/Users/ramtinabolfazli/Documents/Work/Seniors and Juniors/Program/output\" --uploads_root \"/Users/ramtinabolfazli/Documents/Work/Seniors and Juniors/Program/uploads\"\nusage: process_jha.py [-h] --uploads_root UPLOADS_ROOT --location LOCATION\nprocess_jha.py: error: unrecognized arguments: --output /Users/ramtinabolfazli/Documents/Work/Seniors and Juniors/Program/output\n","stack":"Error: Command failed: python \"/Users/ramtinabolfazli/Documents/Work/Seniors and Juniors/Program/server/python/process_jha.py\" --location \"12345\" --output \"/Users/ramtinabolfazli/Documents/Work/Seniors and Juniors/Program/output\" --uploads_root \"/Users/ramtinabolfazli/Documents/Work/Seniors and Juniors/Program/uploads\"\nusage: process_jha.py [-h] --uploads_root UPLOADS_ROOT --location LOCATION\nprocess_jha.py: error: unrecognized arguments: --output /Users/ramtinabolfazli/Documents/Work/Seniors and Juniors/Program/output\n\n    at genericNodeError (node:internal/errors:983:15)\n    at wrappedFn (node:internal/errors:537:14)\n    at ChildProcess.exithandler (node:child_process:414:12)\n    at ChildProcess.emit (node:events:507:28)\n    at maybeClose (node:internal/child_process:1101:16)\n    at Socket.<anonymous> (node:internal/child_process:457:11)\n    at Socket.emit (node:events:507:28)\n    at Pipe.<anonymous> (node:net:350:12)"},"context":{"requestId":1748025660419,"location":"12345"}}
{"timestamp":"2025-05-23T18:49:40.808Z","error":{"name":"Error","message":"Command failed: python \"/Users/ramtinabolfazli/Documents/Work/Seniors and Juniors/Program/server/python/process_jha.py\" --location \"12345\" --uploads_root \"/Users/ramtinabolfazli/Documents/Work/Seniors and Juniors/Program/uploads\"\nTraceback (most recent call last):\n  File \"/Users/ramtinabolfazli/Documents/Work/Seniors and Juniors/Program/server/python/process_jha.py\", line 152, in <module>\n    main()\n  File \"/Users/ramtinabolfazli/Documents/Work/Seniors and Juniors/Program/server/python/process_jha.py\", line 143, in main\n    jha_data = process_pdf_files()\n               ^^^^^^^^^^^^^^^^^^^\n  File \"/Users/ramtinabolfazli/Documents/Work/Seniors and Juniors/Program/server/python/process_jha.py\", line 76, in process_pdf_files\n    pdf_files = sorted(\n                ^^^^^^^\n  File \"/Users/ramtinabolfazli/Documents/Work/Seniors and Juniors/Program/server/python/process_jha.py\", line 78, in <lambda>\n    key=lambda x: datetime.strptime(x.split('.')[0], '%Y-%m-%d')\n                  ^^^^^^^^^^^^^^^^^^^^^^^^^^^^^^^^^^^^^^^^^^^^^^\n  File \"/opt/miniconda3/lib/python3.12/_strptime.py\", line 554, in _strptime_datetime\n    tt, fraction, gmtoff_fraction = _strptime(data_string, format)\n                                    ^^^^^^^^^^^^^^^^^^^^^^^^^^^^^^\n  File \"/opt/miniconda3/lib/python3.12/_strptime.py\", line 336, in _strptime\n    raise ValueError(\"unconverted data remains: %s\" %\nValueError: unconverted data remains:  15-35-06\n","stack":"Error: Command failed: python \"/Users/ramtinabolfazli/Documents/Work/Seniors and Juniors/Program/server/python/process_jha.py\" --location \"12345\" --uploads_root \"/Users/ramtinabolfazli/Documents/Work/Seniors and Juniors/Program/uploads\"\nTraceback (most recent call last):\n  File \"/Users/ramtinabolfazli/Documents/Work/Seniors and Juniors/Program/server/python/process_jha.py\", line 152, in <module>\n    main()\n  File \"/Users/ramtinabolfazli/Documents/Work/Seniors and Juniors/Program/server/python/process_jha.py\", line 143, in main\n    jha_data = process_pdf_files()\n               ^^^^^^^^^^^^^^^^^^^\n  File \"/Users/ramtinabolfazli/Documents/Work/Seniors and Juniors/Program/server/python/process_jha.py\", line 76, in process_pdf_files\n    pdf_files = sorted(\n                ^^^^^^^\n  File \"/Users/ramtinabolfazli/Documents/Work/Seniors and Juniors/Program/server/python/process_jha.py\", line 78, in <lambda>\n    key=lambda x: datetime.strptime(x.split('.')[0], '%Y-%m-%d')\n                  ^^^^^^^^^^^^^^^^^^^^^^^^^^^^^^^^^^^^^^^^^^^^^^\n  File \"/opt/miniconda3/lib/python3.12/_strptime.py\", line 554, in _strptime_datetime\n    tt, fraction, gmtoff_fraction = _strptime(data_string, format)\n                                    ^^^^^^^^^^^^^^^^^^^^^^^^^^^^^^\n  File \"/opt/miniconda3/lib/python3.12/_strptime.py\", line 336, in _strptime\n    raise ValueError(\"unconverted data remains: %s\" %\nValueError: unconverted data remains:  15-35-06\n\n    at genericNodeError (node:internal/errors:983:15)\n    at wrappedFn (node:internal/errors:537:14)\n    at ChildProcess.exithandler (node:child_process:414:12)\n    at ChildProcess.emit (node:events:507:28)\n    at maybeClose (node:internal/child_process:1101:16)\n    at ChildProcess._handle.onexit (node:internal/child_process:305:5)"},"context":{"requestId":1748026177119,"location":"12345"}}
{"timestamp":"2025-05-23T19:32:53.652Z","error":{"name":"Error","message":"Command failed: python \"/Users/ramtinabolfazli/Documents/Work/Seniors and Juniors/Program/server/python/process_jha.py\" --location \"12345\" --uploads_root \"/Users/ramtinabolfazli/Documents/Work/Seniors and Juniors/Program/uploads\"\nTraceback (most recent call last):\n  File \"/Users/ramtinabolfazli/Documents/Work/Seniors and Juniors/Program/server/python/process_jha.py\", line 152, in <module>\n    main()\n  File \"/Users/ramtinabolfazli/Documents/Work/Seniors and Juniors/Program/server/python/process_jha.py\", line 143, in main\n    jha_data = process_pdf_files()\n               ^^^^^^^^^^^^^^^^^^^\n  File \"/Users/ramtinabolfazli/Documents/Work/Seniors and Juniors/Program/server/python/process_jha.py\", line 76, in process_pdf_files\n    pdf_files = sorted(\n                ^^^^^^^\n  File \"/Users/ramtinabolfazli/Documents/Work/Seniors and Juniors/Program/server/python/process_jha.py\", line 78, in <lambda>\n    key=lambda x: datetime.strptime(x.split('.')[0], '%Y-%m-%d')\n                  ^^^^^^^^^^^^^^^^^^^^^^^^^^^^^^^^^^^^^^^^^^^^^^\n  File \"/opt/miniconda3/lib/python3.12/_strptime.py\", line 554, in _strptime_datetime\n    tt, fraction, gmtoff_fraction = _strptime(data_string, format)\n                                    ^^^^^^^^^^^^^^^^^^^^^^^^^^^^^^\n  File \"/opt/miniconda3/lib/python3.12/_strptime.py\", line 336, in _strptime\n    raise ValueError(\"unconverted data remains: %s\" %\nValueError: unconverted data remains:  15-35-06\n","stack":"Error: Command failed: python \"/Users/ramtinabolfazli/Documents/Work/Seniors and Juniors/Program/server/python/process_jha.py\" --location \"12345\" --uploads_root \"/Users/ramtinabolfazli/Documents/Work/Seniors and Juniors/Program/uploads\"\nTraceback (most recent call last):\n  File \"/Users/ramtinabolfazli/Documents/Work/Seniors and Juniors/Program/server/python/process_jha.py\", line 152, in <module>\n    main()\n  File \"/Users/ramtinabolfazli/Documents/Work/Seniors and Juniors/Program/server/python/process_jha.py\", line 143, in main\n    jha_data = process_pdf_files()\n               ^^^^^^^^^^^^^^^^^^^\n  File \"/Users/ramtinabolfazli/Documents/Work/Seniors and Juniors/Program/server/python/process_jha.py\", line 76, in process_pdf_files\n    pdf_files = sorted(\n                ^^^^^^^\n  File \"/Users/ramtinabolfazli/Documents/Work/Seniors and Juniors/Program/server/python/process_jha.py\", line 78, in <lambda>\n    key=lambda x: datetime.strptime(x.split('.')[0], '%Y-%m-%d')\n                  ^^^^^^^^^^^^^^^^^^^^^^^^^^^^^^^^^^^^^^^^^^^^^^\n  File \"/opt/miniconda3/lib/python3.12/_strptime.py\", line 554, in _strptime_datetime\n    tt, fraction, gmtoff_fraction = _strptime(data_string, format)\n                                    ^^^^^^^^^^^^^^^^^^^^^^^^^^^^^^\n  File \"/opt/miniconda3/lib/python3.12/_strptime.py\", line 336, in _strptime\n    raise ValueError(\"unconverted data remains: %s\" %\nValueError: unconverted data remains:  15-35-06\n\n    at genericNodeError (node:internal/errors:983:15)\n    at wrappedFn (node:internal/errors:537:14)\n    at ChildProcess.exithandler (node:child_process:414:12)\n    at ChildProcess.emit (node:events:507:28)\n    at maybeClose (node:internal/child_process:1101:16)\n    at ChildProcess._handle.onexit (node:internal/child_process:305:5)"},"context":{"requestId":1748028770072,"location":"12345"}}
{"timestamp":"2025-05-23T19:34:54.487Z","error":{"name":"Error","message":"Command failed: python \"/Users/ramtinabolfazli/Documents/Work/Seniors and Juniors/Program/server/python/process_jha.py\" --location \"12345\" --uploads_root \"/Users/ramtinabolfazli/Documents/Work/Seniors and Juniors/Program/uploads\"\nTraceback (most recent call last):\n  File \"/Users/ramtinabolfazli/Documents/Work/Seniors and Juniors/Program/server/python/process_jha.py\", line 152, in <module>\n    main()\n  File \"/Users/ramtinabolfazli/Documents/Work/Seniors and Juniors/Program/server/python/process_jha.py\", line 143, in main\n    jha_data = process_pdf_files()\n               ^^^^^^^^^^^^^^^^^^^\n  File \"/Users/ramtinabolfazli/Documents/Work/Seniors and Juniors/Program/server/python/process_jha.py\", line 84, in process_pdf_files\n    date = datetime.strptime(date_str, '%Y-%m-%d').date()\n           ^^^^^^^^^^^^^^^^^^^^^^^^^^^^^^^^^^^^^^^\n  File \"/opt/miniconda3/lib/python3.12/_strptime.py\", line 554, in _strptime_datetime\n    tt, fraction, gmtoff_fraction = _strptime(data_string, format)\n                                    ^^^^^^^^^^^^^^^^^^^^^^^^^^^^^^\n  File \"/opt/miniconda3/lib/python3.12/_strptime.py\", line 336, in _strptime\n    raise ValueError(\"unconverted data remains: %s\" %\nValueError: unconverted data remains:  15-35-06\n","stack":"Error: Command failed: python \"/Users/ramtinabolfazli/Documents/Work/Seniors and Juniors/Program/server/python/process_jha.py\" --location \"12345\" --uploads_root \"/Users/ramtinabolfazli/Documents/Work/Seniors and Juniors/Program/uploads\"\nTraceback (most recent call last):\n  File \"/Users/ramtinabolfazli/Documents/Work/Seniors and Juniors/Program/server/python/process_jha.py\", line 152, in <module>\n    main()\n  File \"/Users/ramtinabolfazli/Documents/Work/Seniors and Juniors/Program/server/python/process_jha.py\", line 143, in main\n    jha_data = process_pdf_files()\n               ^^^^^^^^^^^^^^^^^^^\n  File \"/Users/ramtinabolfazli/Documents/Work/Seniors and Juniors/Program/server/python/process_jha.py\", line 84, in process_pdf_files\n    date = datetime.strptime(date_str, '%Y-%m-%d').date()\n           ^^^^^^^^^^^^^^^^^^^^^^^^^^^^^^^^^^^^^^^\n  File \"/opt/miniconda3/lib/python3.12/_strptime.py\", line 554, in _strptime_datetime\n    tt, fraction, gmtoff_fraction = _strptime(data_string, format)\n                                    ^^^^^^^^^^^^^^^^^^^^^^^^^^^^^^\n  File \"/opt/miniconda3/lib/python3.12/_strptime.py\", line 336, in _strptime\n    raise ValueError(\"unconverted data remains: %s\" %\nValueError: unconverted data remains:  15-35-06\n\n    at genericNodeError (node:internal/errors:983:15)\n    at wrappedFn (node:internal/errors:537:14)\n    at ChildProcess.exithandler (node:child_process:414:12)\n    at ChildProcess.emit (node:events:507:28)\n    at maybeClose (node:internal/child_process:1101:16)\n    at ChildProcess._handle.onexit (node:internal/child_process:305:5)"},"context":{"requestId":1748028891741,"location":"12345"}}
{"timestamp":"2025-05-23T19:36:49.190Z","error":{"name":"Error","message":"Command failed: python \"/Users/ramtinabolfazli/Documents/Work/Seniors and Juniors/Program/server/python/process_jha.py\" --location \"12345\" --uploads_root \"/Users/ramtinabolfazli/Documents/Work/Seniors and Juniors/Program/uploads\"\nTraceback (most recent call last):\n  File \"/Users/ramtinabolfazli/Documents/Work/Seniors and Juniors/Program/server/python/process_jha.py\", line 152, in <module>\n    main()\n  File \"/Users/ramtinabolfazli/Documents/Work/Seniors and Juniors/Program/server/python/process_jha.py\", line 143, in main\n    jha_data = process_pdf_files()\n               ^^^^^^^^^^^^^^^^^^^\n  File \"/Users/ramtinabolfazli/Documents/Work/Seniors and Juniors/Program/server/python/process_jha.py\", line 76, in process_pdf_files\n    pdf_files = sorted(\n                ^^^^^^^\n  File \"/Users/ramtinabolfazli/Documents/Work/Seniors and Juniors/Program/server/python/process_jha.py\", line 78, in <lambda>\n    key=lambda x: datetime.strptime(x.split('.')[0], '%Y-%m-%d')\n                  ^^^^^^^^^^^^^^^^^^^^^^^^^^^^^^^^^^^^^^^^^^^^^^\n  File \"/opt/miniconda3/lib/python3.12/_strptime.py\", line 554, in _strptime_datetime\n    tt, fraction, gmtoff_fraction = _strptime(data_string, format)\n                                    ^^^^^^^^^^^^^^^^^^^^^^^^^^^^^^\n  File \"/opt/miniconda3/lib/python3.12/_strptime.py\", line 336, in _strptime\n    raise ValueError(\"unconverted data remains: %s\" %\nValueError: unconverted data remains:  15-35-06\n","stack":"Error: Command failed: python \"/Users/ramtinabolfazli/Documents/Work/Seniors and Juniors/Program/server/python/process_jha.py\" --location \"12345\" --uploads_root \"/Users/ramtinabolfazli/Documents/Work/Seniors and Juniors/Program/uploads\"\nTraceback (most recent call last):\n  File \"/Users/ramtinabolfazli/Documents/Work/Seniors and Juniors/Program/server/python/process_jha.py\", line 152, in <module>\n    main()\n  File \"/Users/ramtinabolfazli/Documents/Work/Seniors and Juniors/Program/server/python/process_jha.py\", line 143, in main\n    jha_data = process_pdf_files()\n               ^^^^^^^^^^^^^^^^^^^\n  File \"/Users/ramtinabolfazli/Documents/Work/Seniors and Juniors/Program/server/python/process_jha.py\", line 76, in process_pdf_files\n    pdf_files = sorted(\n                ^^^^^^^\n  File \"/Users/ramtinabolfazli/Documents/Work/Seniors and Juniors/Program/server/python/process_jha.py\", line 78, in <lambda>\n    key=lambda x: datetime.strptime(x.split('.')[0], '%Y-%m-%d')\n                  ^^^^^^^^^^^^^^^^^^^^^^^^^^^^^^^^^^^^^^^^^^^^^^\n  File \"/opt/miniconda3/lib/python3.12/_strptime.py\", line 554, in _strptime_datetime\n    tt, fraction, gmtoff_fraction = _strptime(data_string, format)\n                                    ^^^^^^^^^^^^^^^^^^^^^^^^^^^^^^\n  File \"/opt/miniconda3/lib/python3.12/_strptime.py\", line 336, in _strptime\n    raise ValueError(\"unconverted data remains: %s\" %\nValueError: unconverted data remains:  15-35-06\n\n    at genericNodeError (node:internal/errors:983:15)\n    at wrappedFn (node:internal/errors:537:14)\n    at ChildProcess.exithandler (node:child_process:414:12)\n    at ChildProcess.emit (node:events:507:28)\n    at maybeClose (node:internal/child_process:1101:16)\n    at ChildProcess._handle.onexit (node:internal/child_process:305:5)"},"context":{"requestId":1748029006440,"location":"12345"}}
{"timestamp":"2025-05-23T19:38:15.861Z","error":{"name":"Error","message":"Command failed: python \"/Users/ramtinabolfazli/Documents/Work/Seniors and Juniors/Program/server/python/process_jha.py\" --location \"12345\" --uploads_root \"/Users/ramtinabolfazli/Documents/Work/Seniors and Juniors/Program/uploads\"\nTraceback (most recent call last):\n  File \"/Users/ramtinabolfazli/Documents/Work/Seniors and Juniors/Program/server/python/process_jha.py\", line 152, in <module>\n    main()\n  File \"/Users/ramtinabolfazli/Documents/Work/Seniors and Juniors/Program/server/python/process_jha.py\", line 147, in main\n    update_excel_file(jha_data)\n  File \"/Users/ramtinabolfazli/Documents/Work/Seniors and Juniors/Program/server/python/process_jha.py\", line 103, in update_excel_file\n    with pd.ExcelFile(EXCEL_TEMPLATE) as xls:\n         ^^^^^^^^^^^^^^^^^^^^^^^^^^^^\n  File \"/opt/miniconda3/lib/python3.12/site-packages/pandas/io/excel/_base.py\", line 1550, in __init__\n    ext = inspect_excel_format(\n          ^^^^^^^^^^^^^^^^^^^^^\n  File \"/opt/miniconda3/lib/python3.12/site-packages/pandas/io/excel/_base.py\", line 1402, in inspect_excel_format\n    with get_handle(\n         ^^^^^^^^^^^\n  File \"/opt/miniconda3/lib/python3.12/site-packages/pandas/io/common.py\", line 882, in get_handle\n    handle = open(handle, ioargs.mode)\n             ^^^^^^^^^^^^^^^^^^^^^^^^^\nIsADirectoryError: [Errno 21] Is a directory: '/Users/ramtinabolfazli/Documents/Work/Seniors and Juniors/Program/uploads/jha/12345/excel'\n","stack":"Error: Command failed: python \"/Users/ramtinabolfazli/Documents/Work/Seniors and Juniors/Program/server/python/process_jha.py\" --location \"12345\" --uploads_root \"/Users/ramtinabolfazli/Documents/Work/Seniors and Juniors/Program/uploads\"\nTraceback (most recent call last):\n  File \"/Users/ramtinabolfazli/Documents/Work/Seniors and Juniors/Program/server/python/process_jha.py\", line 152, in <module>\n    main()\n  File \"/Users/ramtinabolfazli/Documents/Work/Seniors and Juniors/Program/server/python/process_jha.py\", line 147, in main\n    update_excel_file(jha_data)\n  File \"/Users/ramtinabolfazli/Documents/Work/Seniors and Juniors/Program/server/python/process_jha.py\", line 103, in update_excel_file\n    with pd.ExcelFile(EXCEL_TEMPLATE) as xls:\n         ^^^^^^^^^^^^^^^^^^^^^^^^^^^^\n  File \"/opt/miniconda3/lib/python3.12/site-packages/pandas/io/excel/_base.py\", line 1550, in __init__\n    ext = inspect_excel_format(\n          ^^^^^^^^^^^^^^^^^^^^^\n  File \"/opt/miniconda3/lib/python3.12/site-packages/pandas/io/excel/_base.py\", line 1402, in inspect_excel_format\n    with get_handle(\n         ^^^^^^^^^^^\n  File \"/opt/miniconda3/lib/python3.12/site-packages/pandas/io/common.py\", line 882, in get_handle\n    handle = open(handle, ioargs.mode)\n             ^^^^^^^^^^^^^^^^^^^^^^^^^\nIsADirectoryError: [Errno 21] Is a directory: '/Users/ramtinabolfazli/Documents/Work/Seniors and Juniors/Program/uploads/jha/12345/excel'\n\n    at genericNodeError (node:internal/errors:983:15)\n    at wrappedFn (node:internal/errors:537:14)\n    at ChildProcess.exithandler (node:child_process:414:12)\n    at ChildProcess.emit (node:events:507:28)\n    at maybeClose (node:internal/child_process:1101:16)\n    at Socket.<anonymous> (node:internal/child_process:457:11)\n    at Socket.emit (node:events:507:28)\n    at Pipe.<anonymous> (node:net:350:12)"},"context":{"requestId":1748029087229,"location":"12345"}}
{"timestamp":"2025-05-23T20:17:38.236Z","error":{"name":"Error","message":"Command failed: python \"/Users/ramtinabolfazli/Documents/Work/Seniors and Juniors/Program/server/python/process_jha.py\" --location \"12345\" --uploads_root \"/Users/ramtinabolfazli/Documents/Work/Seniors and Juniors/Program/uploads\"\nTraceback (most recent call last):\n  File \"/Users/ramtinabolfazli/Documents/Work/Seniors and Juniors/Program/server/python/process_jha.py\", line 152, in <module>\n    main()\n  File \"/Users/ramtinabolfazli/Documents/Work/Seniors and Juniors/Program/server/python/process_jha.py\", line 143, in main\n    jha_data = process_pdf_files()\n               ^^^^^^^^^^^^^^^^^^^\n  File \"/Users/ramtinabolfazli/Documents/Work/Seniors and Juniors/Program/server/python/process_jha.py\", line 88, in process_pdf_files\n    data = parse_pdf_with_ai(pdf_text)\n           ^^^^^^^^^^^^^^^^^^^^^^^^^^^\n  File \"/Users/ramtinabolfazli/Documents/Work/Seniors and Juniors/Program/server/python/process_jha.py\", line 62, in parse_pdf_with_ai\n    response = client.chat.completions.create(\n               ^^^^^^^^^^^^^^^^^^^^^^^^^^^^^^^\n  File \"/opt/miniconda3/lib/python3.12/site-packages/openai/_utils/_utils.py\", line 287, in wrapper\n    return func(*args, **kwargs)\n           ^^^^^^^^^^^^^^^^^^^^^\n  File \"/opt/miniconda3/lib/python3.12/site-packages/openai/resources/chat/completions/completions.py\", line 925, in create\n    return self._post(\n           ^^^^^^^^^^^\n  File \"/opt/miniconda3/lib/python3.12/site-packages/openai/_base_client.py\", line 1239, in post\n    return cast(ResponseT, self.request(cast_to, opts, stream=stream, stream_cls=stream_cls))\n                           ^^^^^^^^^^^^^^^^^^^^^^^^^^^^^^^^^^^^^^^^^^^^^^^^^^^^^^^^^^^^^^^^^\n  File \"/opt/miniconda3/lib/python3.12/site-packages/openai/_base_client.py\", line 1034, in request\n    raise self._make_status_error_from_response(err.response) from None\nopenai.BadRequestError: Error code: 400 - {'error': {'message': \"Unsupported value: 'temperature' does not support 0.1 with this model. Only the default (1) value is supported.\", 'type': 'invalid_request_error', 'param': 'temperature', 'code': 'unsupported_value'}}\n","stack":"Error: Command failed: python \"/Users/ramtinabolfazli/Documents/Work/Seniors and Juniors/Program/server/python/process_jha.py\" --location \"12345\" --uploads_root \"/Users/ramtinabolfazli/Documents/Work/Seniors and Juniors/Program/uploads\"\nTraceback (most recent call last):\n  File \"/Users/ramtinabolfazli/Documents/Work/Seniors and Juniors/Program/server/python/process_jha.py\", line 152, in <module>\n    main()\n  File \"/Users/ramtinabolfazli/Documents/Work/Seniors and Juniors/Program/server/python/process_jha.py\", line 143, in main\n    jha_data = process_pdf_files()\n               ^^^^^^^^^^^^^^^^^^^\n  File \"/Users/ramtinabolfazli/Documents/Work/Seniors and Juniors/Program/server/python/process_jha.py\", line 88, in process_pdf_files\n    data = parse_pdf_with_ai(pdf_text)\n           ^^^^^^^^^^^^^^^^^^^^^^^^^^^\n  File \"/Users/ramtinabolfazli/Documents/Work/Seniors and Juniors/Program/server/python/process_jha.py\", line 62, in parse_pdf_with_ai\n    response = client.chat.completions.create(\n               ^^^^^^^^^^^^^^^^^^^^^^^^^^^^^^^\n  File \"/opt/miniconda3/lib/python3.12/site-packages/openai/_utils/_utils.py\", line 287, in wrapper\n    return func(*args, **kwargs)\n           ^^^^^^^^^^^^^^^^^^^^^\n  File \"/opt/miniconda3/lib/python3.12/site-packages/openai/resources/chat/completions/completions.py\", line 925, in create\n    return self._post(\n           ^^^^^^^^^^^\n  File \"/opt/miniconda3/lib/python3.12/site-packages/openai/_base_client.py\", line 1239, in post\n    return cast(ResponseT, self.request(cast_to, opts, stream=stream, stream_cls=stream_cls))\n                           ^^^^^^^^^^^^^^^^^^^^^^^^^^^^^^^^^^^^^^^^^^^^^^^^^^^^^^^^^^^^^^^^^\n  File \"/opt/miniconda3/lib/python3.12/site-packages/openai/_base_client.py\", line 1034, in request\n    raise self._make_status_error_from_response(err.response) from None\nopenai.BadRequestError: Error code: 400 - {'error': {'message': \"Unsupported value: 'temperature' does not support 0.1 with this model. Only the default (1) value is supported.\", 'type': 'invalid_request_error', 'param': 'temperature', 'code': 'unsupported_value'}}\n\n    at genericNodeError (node:internal/errors:983:15)\n    at wrappedFn (node:internal/errors:537:14)\n    at ChildProcess.exithandler (node:child_process:414:12)\n    at ChildProcess.emit (node:events:507:28)\n    at maybeClose (node:internal/child_process:1101:16)\n    at Socket.<anonymous> (node:internal/child_process:457:11)\n    at Socket.emit (node:events:507:28)\n    at Pipe.<anonymous> (node:net:350:12)"},"context":{"requestId":1748031452662,"location":"12345"}}
{"timestamp":"2025-05-23T20:18:23.636Z","error":{"name":"Error","message":"Command failed: python \"/Users/ramtinabolfazli/Documents/Work/Seniors and Juniors/Program/server/python/process_jha.py\" --location \"12345\" --uploads_root \"/Users/ramtinabolfazli/Documents/Work/Seniors and Juniors/Program/uploads\"\nTraceback (most recent call last):\n  File \"/Users/ramtinabolfazli/Documents/Work/Seniors and Juniors/Program/server/python/process_jha.py\", line 151, in <module>\n    main()\n  File \"/Users/ramtinabolfazli/Documents/Work/Seniors and Juniors/Program/server/python/process_jha.py\", line 146, in main\n    update_excel_file(jha_data)\n  File \"/Users/ramtinabolfazli/Documents/Work/Seniors and Juniors/Program/server/python/process_jha.py\", line 102, in update_excel_file\n    with pd.ExcelFile(EXCEL_TEMPLATE) as xls:\n         ^^^^^^^^^^^^^^^^^^^^^^^^^^^^\n  File \"/opt/miniconda3/lib/python3.12/site-packages/pandas/io/excel/_base.py\", line 1550, in __init__\n    ext = inspect_excel_format(\n          ^^^^^^^^^^^^^^^^^^^^^\n  File \"/opt/miniconda3/lib/python3.12/site-packages/pandas/io/excel/_base.py\", line 1402, in inspect_excel_format\n    with get_handle(\n         ^^^^^^^^^^^\n  File \"/opt/miniconda3/lib/python3.12/site-packages/pandas/io/common.py\", line 882, in get_handle\n    handle = open(handle, ioargs.mode)\n             ^^^^^^^^^^^^^^^^^^^^^^^^^\nIsADirectoryError: [Errno 21] Is a directory: '/Users/ramtinabolfazli/Documents/Work/Seniors and Juniors/Program/uploads/jha/12345/excel'\n","stack":"Error: Command failed: python \"/Users/ramtinabolfazli/Documents/Work/Seniors and Juniors/Program/server/python/process_jha.py\" --location \"12345\" --uploads_root \"/Users/ramtinabolfazli/Documents/Work/Seniors and Juniors/Program/uploads\"\nTraceback (most recent call last):\n  File \"/Users/ramtinabolfazli/Documents/Work/Seniors and Juniors/Program/server/python/process_jha.py\", line 151, in <module>\n    main()\n  File \"/Users/ramtinabolfazli/Documents/Work/Seniors and Juniors/Program/server/python/process_jha.py\", line 146, in main\n    update_excel_file(jha_data)\n  File \"/Users/ramtinabolfazli/Documents/Work/Seniors and Juniors/Program/server/python/process_jha.py\", line 102, in update_excel_file\n    with pd.ExcelFile(EXCEL_TEMPLATE) as xls:\n         ^^^^^^^^^^^^^^^^^^^^^^^^^^^^\n  File \"/opt/miniconda3/lib/python3.12/site-packages/pandas/io/excel/_base.py\", line 1550, in __init__\n    ext = inspect_excel_format(\n          ^^^^^^^^^^^^^^^^^^^^^\n  File \"/opt/miniconda3/lib/python3.12/site-packages/pandas/io/excel/_base.py\", line 1402, in inspect_excel_format\n    with get_handle(\n         ^^^^^^^^^^^\n  File \"/opt/miniconda3/lib/python3.12/site-packages/pandas/io/common.py\", line 882, in get_handle\n    handle = open(handle, ioargs.mode)\n             ^^^^^^^^^^^^^^^^^^^^^^^^^\nIsADirectoryError: [Errno 21] Is a directory: '/Users/ramtinabolfazli/Documents/Work/Seniors and Juniors/Program/uploads/jha/12345/excel'\n\n    at genericNodeError (node:internal/errors:983:15)\n    at wrappedFn (node:internal/errors:537:14)\n    at ChildProcess.exithandler (node:child_process:414:12)\n    at ChildProcess.emit (node:events:507:28)\n    at maybeClose (node:internal/child_process:1101:16)\n    at ChildProcess._handle.onexit (node:internal/child_process:305:5)"},"context":{"requestId":1748031484752,"location":"12345"}}
{"timestamp":"2025-05-23T20:26:28.020Z","error":{"name":"Error","message":"Command failed: python \"/Users/ramtinabolfazli/Documents/Work/Seniors and Juniors/Program/server/python/process_jha.py\" --location \"12345\" --uploads_root \"/Users/ramtinabolfazli/Documents/Work/Seniors and Juniors/Program/uploads\"\nTraceback (most recent call last):\n  File \"/Users/ramtinabolfazli/Documents/Work/Seniors and Juniors/Program/server/python/process_jha.py\", line 163, in <module>\n    main()\n  File \"/Users/ramtinabolfazli/Documents/Work/Seniors and Juniors/Program/server/python/process_jha.py\", line 158, in main\n    update_excel_file(jha_data)\n  File \"/Users/ramtinabolfazli/Documents/Work/Seniors and Juniors/Program/server/python/process_jha.py\", line 111, in update_excel_file\n    raise FileNotFoundError(f\"No Excel (.xlsx) file found in directory: {excel_dir}\")\nFileNotFoundError: No Excel (.xlsx) file found in directory: /Users/ramtinabolfazli/Documents/Work/Seniors and Juniors/Program/uploads/jha/12345/excel\n","stack":"Error: Command failed: python \"/Users/ramtinabolfazli/Documents/Work/Seniors and Juniors/Program/server/python/process_jha.py\" --location \"12345\" --uploads_root \"/Users/ramtinabolfazli/Documents/Work/Seniors and Juniors/Program/uploads\"\nTraceback (most recent call last):\n  File \"/Users/ramtinabolfazli/Documents/Work/Seniors and Juniors/Program/server/python/process_jha.py\", line 163, in <module>\n    main()\n  File \"/Users/ramtinabolfazli/Documents/Work/Seniors and Juniors/Program/server/python/process_jha.py\", line 158, in main\n    update_excel_file(jha_data)\n  File \"/Users/ramtinabolfazli/Documents/Work/Seniors and Juniors/Program/server/python/process_jha.py\", line 111, in update_excel_file\n    raise FileNotFoundError(f\"No Excel (.xlsx) file found in directory: {excel_dir}\")\nFileNotFoundError: No Excel (.xlsx) file found in directory: /Users/ramtinabolfazli/Documents/Work/Seniors and Juniors/Program/uploads/jha/12345/excel\n\n    at genericNodeError (node:internal/errors:983:15)\n    at wrappedFn (node:internal/errors:537:14)\n    at ChildProcess.exithandler (node:child_process:414:12)\n    at ChildProcess.emit (node:events:507:28)\n    at maybeClose (node:internal/child_process:1101:16)\n    at Socket.<anonymous> (node:internal/child_process:457:11)\n    at Socket.emit (node:events:507:28)\n    at Pipe.<anonymous> (node:net:350:12)"},"context":{"requestId":1748031971199,"location":"12345"}}
{"timestamp":"2025-05-23T20:29:00.094Z","error":{"name":"Error","message":"Command failed: python \"/Users/ramtinabolfazli/Documents/Work/Seniors and Juniors/Program/server/python/process_jha.py\" --location \"12345\" --uploads_root \"/Users/ramtinabolfazli/Documents/Work/Seniors and Juniors/Program/uploads\"\nTraceback (most recent call last):\n  File \"/Users/ramtinabolfazli/Documents/Work/Seniors and Juniors/Program/server/python/process_jha.py\", line 163, in <module>\n    main()\n  File \"/Users/ramtinabolfazli/Documents/Work/Seniors and Juniors/Program/server/python/process_jha.py\", line 158, in main\n    update_excel_file(jha_data)\n  File \"/Users/ramtinabolfazli/Documents/Work/Seniors and Juniors/Program/server/python/process_jha.py\", line 114, in update_excel_file\n    with pd.ExcelFile(EXCEL_TEMPLATE) as xls:\n         ^^^^^^^^^^^^^^^^^^^^^^^^^^^^\n  File \"/opt/miniconda3/lib/python3.12/site-packages/pandas/io/excel/_base.py\", line 1550, in __init__\n    ext = inspect_excel_format(\n          ^^^^^^^^^^^^^^^^^^^^^\n  File \"/opt/miniconda3/lib/python3.12/site-packages/pandas/io/excel/_base.py\", line 1402, in inspect_excel_format\n    with get_handle(\n         ^^^^^^^^^^^\n  File \"/opt/miniconda3/lib/python3.12/site-packages/pandas/io/common.py\", line 882, in get_handle\n    handle = open(handle, ioargs.mode)\n             ^^^^^^^^^^^^^^^^^^^^^^^^^\nIsADirectoryError: [Errno 21] Is a directory: '/Users/ramtinabolfazli/Documents/Work/Seniors and Juniors/Program/uploads/jha/12345/excel'\n","stack":"Error: Command failed: python \"/Users/ramtinabolfazli/Documents/Work/Seniors and Juniors/Program/server/python/process_jha.py\" --location \"12345\" --uploads_root \"/Users/ramtinabolfazli/Documents/Work/Seniors and Juniors/Program/uploads\"\nTraceback (most recent call last):\n  File \"/Users/ramtinabolfazli/Documents/Work/Seniors and Juniors/Program/server/python/process_jha.py\", line 163, in <module>\n    main()\n  File \"/Users/ramtinabolfazli/Documents/Work/Seniors and Juniors/Program/server/python/process_jha.py\", line 158, in main\n    update_excel_file(jha_data)\n  File \"/Users/ramtinabolfazli/Documents/Work/Seniors and Juniors/Program/server/python/process_jha.py\", line 114, in update_excel_file\n    with pd.ExcelFile(EXCEL_TEMPLATE) as xls:\n         ^^^^^^^^^^^^^^^^^^^^^^^^^^^^\n  File \"/opt/miniconda3/lib/python3.12/site-packages/pandas/io/excel/_base.py\", line 1550, in __init__\n    ext = inspect_excel_format(\n          ^^^^^^^^^^^^^^^^^^^^^\n  File \"/opt/miniconda3/lib/python3.12/site-packages/pandas/io/excel/_base.py\", line 1402, in inspect_excel_format\n    with get_handle(\n         ^^^^^^^^^^^\n  File \"/opt/miniconda3/lib/python3.12/site-packages/pandas/io/common.py\", line 882, in get_handle\n    handle = open(handle, ioargs.mode)\n             ^^^^^^^^^^^^^^^^^^^^^^^^^\nIsADirectoryError: [Errno 21] Is a directory: '/Users/ramtinabolfazli/Documents/Work/Seniors and Juniors/Program/uploads/jha/12345/excel'\n\n    at genericNodeError (node:internal/errors:983:15)\n    at wrappedFn (node:internal/errors:537:14)\n    at ChildProcess.exithandler (node:child_process:414:12)\n    at ChildProcess.emit (node:events:507:28)\n    at maybeClose (node:internal/child_process:1101:16)\n    at Socket.<anonymous> (node:internal/child_process:457:11)\n    at Socket.emit (node:events:507:28)\n    at Pipe.<anonymous> (node:net:350:12)"},"context":{"requestId":1748032122286,"location":"12345"}}
{"timestamp":"2025-05-24T02:47:06.952Z","error":{"name":"Error","message":"Command failed: python \"/Users/ramtinabolfazli/Documents/Work/Seniors and Juniors/Program/server/python/process_jha.py\" --location \"12345\" --uploads_root \"/Users/ramtinabolfazli/Documents/Work/Seniors and Juniors/Program/uploads\"\nTraceback (most recent call last):\n  File \"/Users/ramtinabolfazli/Documents/Work/Seniors and Juniors/Program/server/python/process_jha.py\", line 163, in <module>\n    main()\n  File \"/Users/ramtinabolfazli/Documents/Work/Seniors and Juniors/Program/server/python/process_jha.py\", line 158, in main\n    update_excel_file(jha_data)\n  File \"/Users/ramtinabolfazli/Documents/Work/Seniors and Juniors/Program/server/python/process_jha.py\", line 114, in update_excel_file\n    with pd.ExcelFile(EXCEL_TEMPLATE) as xls:\n         ^^^^^^^^^^^^^^^^^^^^^^^^^^^^\n  File \"/opt/miniconda3/lib/python3.12/site-packages/pandas/io/excel/_base.py\", line 1550, in __init__\n    ext = inspect_excel_format(\n          ^^^^^^^^^^^^^^^^^^^^^\n  File \"/opt/miniconda3/lib/python3.12/site-packages/pandas/io/excel/_base.py\", line 1402, in inspect_excel_format\n    with get_handle(\n         ^^^^^^^^^^^\n  File \"/opt/miniconda3/lib/python3.12/site-packages/pandas/io/common.py\", line 882, in get_handle\n    handle = open(handle, ioargs.mode)\n             ^^^^^^^^^^^^^^^^^^^^^^^^^\nIsADirectoryError: [Errno 21] Is a directory: '/Users/ramtinabolfazli/Documents/Work/Seniors and Juniors/Program/uploads/jha/12345/excel'\n","stack":"Error: Command failed: python \"/Users/ramtinabolfazli/Documents/Work/Seniors and Juniors/Program/server/python/process_jha.py\" --location \"12345\" --uploads_root \"/Users/ramtinabolfazli/Documents/Work/Seniors and Juniors/Program/uploads\"\nTraceback (most recent call last):\n  File \"/Users/ramtinabolfazli/Documents/Work/Seniors and Juniors/Program/server/python/process_jha.py\", line 163, in <module>\n    main()\n  File \"/Users/ramtinabolfazli/Documents/Work/Seniors and Juniors/Program/server/python/process_jha.py\", line 158, in main\n    update_excel_file(jha_data)\n  File \"/Users/ramtinabolfazli/Documents/Work/Seniors and Juniors/Program/server/python/process_jha.py\", line 114, in update_excel_file\n    with pd.ExcelFile(EXCEL_TEMPLATE) as xls:\n         ^^^^^^^^^^^^^^^^^^^^^^^^^^^^\n  File \"/opt/miniconda3/lib/python3.12/site-packages/pandas/io/excel/_base.py\", line 1550, in __init__\n    ext = inspect_excel_format(\n          ^^^^^^^^^^^^^^^^^^^^^\n  File \"/opt/miniconda3/lib/python3.12/site-packages/pandas/io/excel/_base.py\", line 1402, in inspect_excel_format\n    with get_handle(\n         ^^^^^^^^^^^\n  File \"/opt/miniconda3/lib/python3.12/site-packages/pandas/io/common.py\", line 882, in get_handle\n    handle = open(handle, ioargs.mode)\n             ^^^^^^^^^^^^^^^^^^^^^^^^^\nIsADirectoryError: [Errno 21] Is a directory: '/Users/ramtinabolfazli/Documents/Work/Seniors and Juniors/Program/uploads/jha/12345/excel'\n\n    at genericNodeError (node:internal/errors:983:15)\n    at wrappedFn (node:internal/errors:537:14)\n    at ChildProcess.exithandler (node:child_process:414:12)\n    at ChildProcess.emit (node:events:507:28)\n    at maybeClose (node:internal/child_process:1101:16)\n    at Socket.<anonymous> (node:internal/child_process:457:11)\n    at Socket.emit (node:events:507:28)\n    at Pipe.<anonymous> (node:net:350:12)"},"context":{"requestId":1748054812764,"location":"12345"}}
{"timestamp":"2025-05-24T02:50:33.707Z","error":{"name":"Error","message":"Command failed: python \"/Users/ramtinabolfazli/Documents/Work/Seniors and Juniors/Program/server/python/process_jha.py\" --location \"12345\" --uploads_root \"/Users/ramtinabolfazli/Documents/Work/Seniors and Juniors/Program/uploads\"\nTraceback (most recent call last):\n  File \"/opt/miniconda3/lib/python3.12/site-packages/pandas/compat/_optional.py\", line 135, in import_optional_dependency\n    module = importlib.import_module(name)\n             ^^^^^^^^^^^^^^^^^^^^^^^^^^^^^\n  File \"/opt/miniconda3/lib/python3.12/importlib/__init__.py\", line 90, in import_module\n    return _bootstrap._gcd_import(name[level:], package, level)\n           ^^^^^^^^^^^^^^^^^^^^^^^^^^^^^^^^^^^^^^^^^^^^^^^^^^^^\n  File \"<frozen importlib._bootstrap>\", line 1387, in _gcd_import\n  File \"<frozen importlib._bootstrap>\", line 1360, in _find_and_load\n  File \"<frozen importlib._bootstrap>\", line 1324, in _find_and_load_unlocked\nModuleNotFoundError: No module named 'pyxlsb'\n\nDuring handling of the above exception, another exception occurred:\n\nTraceback (most recent call last):\n  File \"/Users/ramtinabolfazli/Documents/Work/Seniors and Juniors/Program/server/python/process_jha.py\", line 163, in <module>\n    main()\n  File \"/Users/ramtinabolfazli/Documents/Work/Seniors and Juniors/Program/server/python/process_jha.py\", line 158, in main\n    update_excel_file(jha_data)\n  File \"/Users/ramtinabolfazli/Documents/Work/Seniors and Juniors/Program/server/python/process_jha.py\", line 114, in update_excel_file\n    with pd.ExcelFile(excel_file) as xls:\n         ^^^^^^^^^^^^^^^^^^^^^^^^\n  File \"/opt/miniconda3/lib/python3.12/site-packages/pandas/io/excel/_base.py\", line 1567, in __init__\n    self._reader = self._engines[engine](\n                   ^^^^^^^^^^^^^^^^^^^^^^\n  File \"/opt/miniconda3/lib/python3.12/site-packages/pandas/io/excel/_pyxlsb.py\", line 43, in __init__\n    import_optional_dependency(\"pyxlsb\")\n  File \"/opt/miniconda3/lib/python3.12/site-packages/pandas/compat/_optional.py\", line 138, in import_optional_dependency\n    raise ImportError(msg)\nImportError: Missing optional dependency 'pyxlsb'.  Use pip or conda to install pyxlsb.\n","stack":"Error: Command failed: python \"/Users/ramtinabolfazli/Documents/Work/Seniors and Juniors/Program/server/python/process_jha.py\" --location \"12345\" --uploads_root \"/Users/ramtinabolfazli/Documents/Work/Seniors and Juniors/Program/uploads\"\nTraceback (most recent call last):\n  File \"/opt/miniconda3/lib/python3.12/site-packages/pandas/compat/_optional.py\", line 135, in import_optional_dependency\n    module = importlib.import_module(name)\n             ^^^^^^^^^^^^^^^^^^^^^^^^^^^^^\n  File \"/opt/miniconda3/lib/python3.12/importlib/__init__.py\", line 90, in import_module\n    return _bootstrap._gcd_import(name[level:], package, level)\n           ^^^^^^^^^^^^^^^^^^^^^^^^^^^^^^^^^^^^^^^^^^^^^^^^^^^^\n  File \"<frozen importlib._bootstrap>\", line 1387, in _gcd_import\n  File \"<frozen importlib._bootstrap>\", line 1360, in _find_and_load\n  File \"<frozen importlib._bootstrap>\", line 1324, in _find_and_load_unlocked\nModuleNotFoundError: No module named 'pyxlsb'\n\nDuring handling of the above exception, another exception occurred:\n\nTraceback (most recent call last):\n  File \"/Users/ramtinabolfazli/Documents/Work/Seniors and Juniors/Program/server/python/process_jha.py\", line 163, in <module>\n    main()\n  File \"/Users/ramtinabolfazli/Documents/Work/Seniors and Juniors/Program/server/python/process_jha.py\", line 158, in main\n    update_excel_file(jha_data)\n  File \"/Users/ramtinabolfazli/Documents/Work/Seniors and Juniors/Program/server/python/process_jha.py\", line 114, in update_excel_file\n    with pd.ExcelFile(excel_file) as xls:\n         ^^^^^^^^^^^^^^^^^^^^^^^^\n  File \"/opt/miniconda3/lib/python3.12/site-packages/pandas/io/excel/_base.py\", line 1567, in __init__\n    self._reader = self._engines[engine](\n                   ^^^^^^^^^^^^^^^^^^^^^^\n  File \"/opt/miniconda3/lib/python3.12/site-packages/pandas/io/excel/_pyxlsb.py\", line 43, in __init__\n    import_optional_dependency(\"pyxlsb\")\n  File \"/opt/miniconda3/lib/python3.12/site-packages/pandas/compat/_optional.py\", line 138, in import_optional_dependency\n    raise ImportError(msg)\nImportError: Missing optional dependency 'pyxlsb'.  Use pip or conda to install pyxlsb.\n\n    at genericNodeError (node:internal/errors:983:15)\n    at wrappedFn (node:internal/errors:537:14)\n    at ChildProcess.exithandler (node:child_process:414:12)\n    at ChildProcess.emit (node:events:507:28)\n    at maybeClose (node:internal/child_process:1101:16)\n    at Socket.<anonymous> (node:internal/child_process:457:11)\n    at Socket.emit (node:events:507:28)\n    at Pipe.<anonymous> (node:net:350:12)"},"context":{"requestId":1748055018680,"location":"12345"}}
{"timestamp":"2025-05-24T02:51:45.774Z","error":{"name":"Error","message":"Expected result file was not generated","stack":"Error: Expected result file was not generated\n    at /Users/ramtinabolfazli/Documents/Work/Seniors and Juniors/Program/server/routes/jhaprocess.js:101:27"},"context":{"requestId":1748055093082,"location":"12345"}}
{"timestamp":"2025-05-24T02:54:31.804Z","error":{"name":"Error","message":"Expected result file was not generated","stack":"Error: Expected result file was not generated\n    at /Users/ramtinabolfazli/Documents/Work/Seniors and Juniors/Program/server/routes/jhaprocess.js:101:27"},"context":{"requestId":1748055259711,"location":"12345"}}
{"timestamp":"2025-05-24T03:00:44.211Z","error":{"name":"Error","message":"Expected result file was not generated","stack":"Error: Expected result file was not generated\n    at /Users/ramtinabolfazli/Documents/Work/Seniors and Juniors/Program/server/routes/jhaprocess.js:101:27"},"context":{"requestId":1748055631809,"location":"12345"}}
{"timestamp":"2025-05-24T03:14:02.227Z","error":{"name":"Error","message":"Command failed: python \"/Users/ramtinabolfazli/Documents/Work/Seniors and Juniors/Program/server/python/process_jha.py\" --location \"12345\" --uploads_root \"/Users/ramtinabolfazli/Documents/Work/Seniors and Juniors/Program/uploads\"\nTraceback (most recent call last):\n  File \"/opt/miniconda3/lib/python3.12/site-packages/xlwings/main.py\", line 5182, in open\n    impl = self.impl(name)\n           ^^^^^^^^^^^^^^^\n  File \"/opt/miniconda3/lib/python3.12/site-packages/xlwings/_xlmac.py\", line 401, in __call__\n    raise KeyError(name_or_index)\nKeyError: '~$jha_excel_12345.xlsb'\n\nDuring handling of the above exception, another exception occurred:\n\nTraceback (most recent call last):\n  File \"/opt/miniconda3/lib/python3.12/site-packages/aeosa/appscript/reference.py\", line 479, in __call__\n    return self.AS_appdata.target().event(self._code, params, atts, codecs=self.AS_appdata).send(timeout, sendflags)\n           ^^^^^^^^^^^^^^^^^^^^^^^^^^^^^^^^^^^^^^^^^^^^^^^^^^^^^^^^^^^^^^^^^^^^^^^^^^^^^^^^^^^^^^^^^^^^^^^^^^^^^^^^^\n  File \"/opt/miniconda3/lib/python3.12/site-packages/aeosa/aem/aemsend.py\", line 92, in send\n    raise EventError(errornum, errormsg, eventresult)\naem.aemsend.EventError: Command failed: Parameter error. (-50)\n\nThe above exception was the direct cause of the following exception:\n\nTraceback (most recent call last):\n  File \"/Users/ramtinabolfazli/Documents/Work/Seniors and Juniors/Program/server/python/process_jha.py\", line 160, in <module>\n    main()\n  File \"/Users/ramtinabolfazli/Documents/Work/Seniors and Juniors/Program/server/python/process_jha.py\", line 155, in main\n    update_excel_file(jha_data)\n  File \"/Users/ramtinabolfazli/Documents/Work/Seniors and Juniors/Program/server/python/process_jha.py\", line 117, in update_excel_file\n    wb = app.books.open(excel_file)\n         ^^^^^^^^^^^^^^^^^^^^^^^^^^\n  File \"/opt/miniconda3/lib/python3.12/site-packages/xlwings/main.py\", line 5189, in open\n    impl = self.impl.open(\n           ^^^^^^^^^^^^^^^\n  File \"/opt/miniconda3/lib/python3.12/site-packages/xlwings/_xlmac.py\", line 453, in open\n    self.app.xl.open_workbook(\n  File \"/opt/miniconda3/lib/python3.12/site-packages/aeosa/appscript/reference.py\", line 515, in __call__\n    raise CommandError(self, (args, kargs), e, self.AS_appdata) from e\nappscript.reference.CommandError: Command failed:\n\t\tOSERROR: -50\n\t\tMESSAGE: Parameter error.\n\t\tCOMMAND: app('/Applications/Microsoft Excel.app', newinstance=(0, 2900676)).open_workbook(workbook_file_name='/Users/ramtinabolfazli/Documents/Work/Seniors and Juniors/Program/uploads/jha/12345/excel/~$jha_excel_12345.xlsb', update_links=k.do_not_update_links, read_only=None, format=None, password=None, write_reserved_password=None, ignore_read_only_recommended=None, origin=None, delimiter=None, editable=None, notify=None, converter=None, add_to_mru=None, timeout=-1)\n","stack":"Error: Command failed: python \"/Users/ramtinabolfazli/Documents/Work/Seniors and Juniors/Program/server/python/process_jha.py\" --location \"12345\" --uploads_root \"/Users/ramtinabolfazli/Documents/Work/Seniors and Juniors/Program/uploads\"\nTraceback (most recent call last):\n  File \"/opt/miniconda3/lib/python3.12/site-packages/xlwings/main.py\", line 5182, in open\n    impl = self.impl(name)\n           ^^^^^^^^^^^^^^^\n  File \"/opt/miniconda3/lib/python3.12/site-packages/xlwings/_xlmac.py\", line 401, in __call__\n    raise KeyError(name_or_index)\nKeyError: '~$jha_excel_12345.xlsb'\n\nDuring handling of the above exception, another exception occurred:\n\nTraceback (most recent call last):\n  File \"/opt/miniconda3/lib/python3.12/site-packages/aeosa/appscript/reference.py\", line 479, in __call__\n    return self.AS_appdata.target().event(self._code, params, atts, codecs=self.AS_appdata).send(timeout, sendflags)\n           ^^^^^^^^^^^^^^^^^^^^^^^^^^^^^^^^^^^^^^^^^^^^^^^^^^^^^^^^^^^^^^^^^^^^^^^^^^^^^^^^^^^^^^^^^^^^^^^^^^^^^^^^^\n  File \"/opt/miniconda3/lib/python3.12/site-packages/aeosa/aem/aemsend.py\", line 92, in send\n    raise EventError(errornum, errormsg, eventresult)\naem.aemsend.EventError: Command failed: Parameter error. (-50)\n\nThe above exception was the direct cause of the following exception:\n\nTraceback (most recent call last):\n  File \"/Users/ramtinabolfazli/Documents/Work/Seniors and Juniors/Program/server/python/process_jha.py\", line 160, in <module>\n    main()\n  File \"/Users/ramtinabolfazli/Documents/Work/Seniors and Juniors/Program/server/python/process_jha.py\", line 155, in main\n    update_excel_file(jha_data)\n  File \"/Users/ramtinabolfazli/Documents/Work/Seniors and Juniors/Program/server/python/process_jha.py\", line 117, in update_excel_file\n    wb = app.books.open(excel_file)\n         ^^^^^^^^^^^^^^^^^^^^^^^^^^\n  File \"/opt/miniconda3/lib/python3.12/site-packages/xlwings/main.py\", line 5189, in open\n    impl = self.impl.open(\n           ^^^^^^^^^^^^^^^\n  File \"/opt/miniconda3/lib/python3.12/site-packages/xlwings/_xlmac.py\", line 453, in open\n    self.app.xl.open_workbook(\n  File \"/opt/miniconda3/lib/python3.12/site-packages/aeosa/appscript/reference.py\", line 515, in __call__\n    raise CommandError(self, (args, kargs), e, self.AS_appdata) from e\nappscript.reference.CommandError: Command failed:\n\t\tOSERROR: -50\n\t\tMESSAGE: Parameter error.\n\t\tCOMMAND: app('/Applications/Microsoft Excel.app', newinstance=(0, 2900676)).open_workbook(workbook_file_name='/Users/ramtinabolfazli/Documents/Work/Seniors and Juniors/Program/uploads/jha/12345/excel/~$jha_excel_12345.xlsb', update_links=k.do_not_update_links, read_only=None, format=None, password=None, write_reserved_password=None, ignore_read_only_recommended=None, origin=None, delimiter=None, editable=None, notify=None, converter=None, add_to_mru=None, timeout=-1)\n\n    at genericNodeError (node:internal/errors:983:15)\n    at wrappedFn (node:internal/errors:537:14)\n    at ChildProcess.exithandler (node:child_process:414:12)\n    at ChildProcess.emit (node:events:507:28)\n    at maybeClose (node:internal/child_process:1101:16)\n    at ChildProcess._handle.onexit (node:internal/child_process:305:5)"},"context":{"requestId":1748056425167,"location":"12345"}}
{"timestamp":"2025-05-24T03:14:39.592Z","error":{"name":"Error","message":"Command failed: python \"/Users/ramtinabolfazli/Documents/Work/Seniors and Juniors/Program/server/python/process_jha.py\" --location \"12345\" --uploads_root \"/Users/ramtinabolfazli/Documents/Work/Seniors and Juniors/Program/uploads\"\n","stack":"Error: Command failed: python \"/Users/ramtinabolfazli/Documents/Work/Seniors and Juniors/Program/server/python/process_jha.py\" --location \"12345\" --uploads_root \"/Users/ramtinabolfazli/Documents/Work/Seniors and Juniors/Program/uploads\"\n\n    at genericNodeError (node:internal/errors:983:15)\n    at wrappedFn (node:internal/errors:537:14)\n    at ChildProcess.exithandler (node:child_process:414:12)\n    at ChildProcess.emit (node:events:507:28)\n    at maybeClose (node:internal/child_process:1101:16)\n    at ChildProcess._handle.onexit (node:internal/child_process:305:5)"},"context":{"requestId":1748056179572,"location":"12345"}}
{"timestamp":"2025-05-24T03:17:30.247Z","error":{"name":"Error","message":"Expected result file was not generated","stack":"Error: Expected result file was not generated\n    at /Users/ramtinabolfazli/Documents/Work/Seniors and Juniors/Program/server/routes/jhaprocess.js:101:27\n    at process.processTicksAndRejections (node:internal/process/task_queues:105:5)"},"context":{"requestId":1748056580124,"location":"12345"}}
{"timestamp":"2025-05-24T03:28:07.106Z","error":{"name":"Error","message":"Expected result file was not generated","stack":"Error: Expected result file was not generated\n    at /Users/ramtinabolfazli/Documents/Work/Seniors and Juniors/Program/server/routes/jhaprocess.js:101:27\n    at process.processTicksAndRejections (node:internal/process/task_queues:105:5)"},"context":{"requestId":1748057261262,"location":"12345"}}
